<?xml version="1.0"?>
<!--不推荐用urdf启动，这是纯urdf，无gazebo插件，推荐使用xacro启动，w1_descrption.xacro仅包含了一层robot标签，其余无改动-->
<robot name="w1_description">

    <material name="black">
        <color rgba="0.0 0.0 0.0 1.0" />
    </material>
    <material name="blue">
        <color rgba="0.0 0.0 0.8 1.0" />
    </material>
    <material name="green">
        <color rgba="0.0 0.8 0.0 1.0" />
    </material>
    <material name="grey">
        <color rgba="0.2 0.2 0.2 1.0" />
    </material>
    <material name="silver">
        <color rgba="0.9137254901960784 0.9137254901960784 0.8470588235294118 1.0" />
    </material>
    <material name="orange">
        <color rgba="1.0 0.4235294117647059 0.0392156862745098 1.0" />
    </material>
    <material name="brown">
        <color rgba="0.8705882352941177 0.8117647058823529 0.7647058823529411 1.0" />
    </material>
    <material name="red">
        <color rgba="0.8 0.0 0.0 1.0" />
    </material>
    <material name="white">
        <color rgba="1.0 1.0 1.0 1.0" />
    </material>

    <link name="base">
        <visual>
          <origin rpy="0 0 0" xyz="0 0 0"/>
          <geometry>
            <box size="0.001 0.001 0.001"/>
          </geometry>
        </visual>
    </link>
    <joint name="floating_base" type="fixed">
      <origin rpy="0 0 0" xyz="0 0 0"/>
      <parent link="base"/>
      <child link="trunk"/>
    </joint>

   <link name="trunk">
        <visual>
            <origin rpy="0 0 0" xyz="0 0 -0.045" />
            <geometry>
                <mesh filename="package://w1_description/meshes/trunk.STL" scale="1 1 1" />
            </geometry>
        </visual>
        <collision>
            <origin rpy="0 0 0" xyz="-0.0455 0 -0.07551" />
            <geometry>
                <box size="1.064 0.265 0.158" />
            </geometry>
        </collision>
        <inertial>
            <origin rpy="0 0 0" xyz="0.00753 -0.00067 -0.04359" />
            <mass value="23.787" />
            <inertia ixx="0.17222073" ixy="0.00339712" ixz="-0.0092304" iyy="1.15539026" iyz="-0.00099682" izz="1.2147365" />
        </inertial>
    </link>
    <!-- Imu is fixed to the trunk link -->
    <joint name="imu_joint" type="fixed">
        <origin rpy="0. 0. 0." xyz="0.0 0.0 0.0" />
        <parent link="trunk" />
        <child link="imu_link" />
    </joint>
    <!-- Imu link -->
    <link name="imu_link">
        <inertial>
            <mass value="0.01" />
            <origin rpy="0 0 0" xyz="0 0 0" />
            <inertia ixx="0.000001" ixy="0" ixz="0" iyy="0.000001" iyz="0" izz="0.000001" />
        </inertial>
        <visual>
            <origin rpy="0 0 0" xyz="0 0 0" />
            <geometry>
                <box size="0.015 0.015 0.004" />
            </geometry>
        </visual>
    </link>

    <joint name="FR_hip_joint" type="revolute">
        <origin rpy="0 0 0" xyz="0.2508 -0.065 -0.045" />
        <parent link="trunk" />
        <child link="FR_hip" />
        <axis xyz="1 0 0" />
        <dynamics damping="0.05" friction="0.01" />
        <limit effort="80" lower="-0.87" upper="0.87" velocity="20" />
    </joint>
    <link name="FR_hip">
        <visual>
            <origin rpy="0 0 0" xyz="0 0 0" />
            <geometry>
                <mesh filename="package://w1_description/meshes/RF_hip.STL" scale="1 1 1" />
            </geometry>
        </visual>
        <inertial>
            <origin rpy="0 0 0" xyz="0.057951 -0.00922 -1.7e-05" />
            <mass value="1.543" />
            <inertia ixx="0.001250053" ixy="3.0903e-05" ixz="-4.03e-06" iyy="0.002049507" iyz="-5.045e-06" izz="0.001568073" />
        </inertial>
    </link>
    <joint name="FR_thigh_joint" type="revolute">
        <origin rpy="0 0 0" xyz="0.064 -0.0363 0" />
        <parent link="FR_hip" />
        <child link="FR_thigh" />
        <axis xyz="0 1 0" />
        <dynamics damping="0.05" friction="0.01" />
        <limit effort="80" lower="-2.27" upper="1.22" velocity="20" />
    </joint>
    <link name="FR_thigh">
        <visual>
            <origin rpy="0 0 0" xyz="0 0 0" />
            <geometry>
                <mesh filename="package://w1_description/meshes/RF_thigh.STL" scale="1 1 1" />
            </geometry>
        </visual>
        <inertial>
            <origin rpy="0 0 0" xyz="-0.061914 -0.061328 0.00435" />
            <mass value="2.997" />
            <inertia ixx="0.005164125" ixy="-0.00579372" ixz="0.001694032" iyy="0.036812985" iyz="0.000522747" izz="0.038207062" />
        </inertial>
    </link>
    <joint name="FR_calf_joint" type="revolute">
        <origin rpy="0 0 0" xyz="-0.28 -0.09075 0" />
        <parent link="FR_thigh" />
        <child link="FR_calf" />
        <axis xyz="0 1 0" />
        <dynamics damping="0.05" friction="0.01" />
        <limit effort="80" lower="0" upper="2.0943951023932" velocity="20" />
    </joint>
    <link name="FR_calf">
        <visual>
            <origin rpy="0 0 0" xyz="0 0 0" />
            <geometry>
                <mesh filename="package://w1_description/meshes/RF_calf.STL" scale="1 1 1" />
            </geometry>
        </visual>
        <collision>
            <origin rpy="0 0.680678408 0" xyz="0.10876 0 -0.08805" />
            <geometry>
                <box size="0.28 0.023 0.0451" />
            </geometry>
        </collision>
        <inertial>
            <origin rpy="0 0 0" xyz="0.175672 -0.004984 -0.145368" />
            <mass value="1.405" />
            <inertia ixx="0.006518228" ixy="0.000248509" ixz="0.006450451" iyy="0.014553507" iyz="-0.000233879" izz="0.008539584" />
        </inertial>
    </link>
    <joint name="FR_foot_joint" type="revolute">
        <origin rpy="0 -0.3 0" xyz="0.21449 -0.03459 -0.17998" />
        <parent link="FR_calf" />
        <child link="FR_foot" />
        <axis xyz="0 1 0" />
        <dynamics friction="1.0" />
        <limit effort="40" lower="-999999" upper="999999" velocity="20" />
    </joint>
    <link name="FR_foot">
        <visual>
            <origin rpy="0 0 0" xyz="0 0 0" />
            <geometry>
                <mesh filename="package://w1_description/meshes/RF_wheel.STL" scale="1 1 1" />
            </geometry>
        </visual>
        <collision>
            <origin rpy="1.5707963267948966 0 0" xyz="0 0 0" />
            <geometry>
                <cylinder length="0.017" radius="0.127" />
            </geometry>
        </collision>
        <inertial>
            <origin rpy="0 0 0" xyz="-3.6e-05 -0.000971 -3.9e-05" />
            <mass value="0.995" />
            <inertia ixx="0.004921306" ixy="-7e-09" ixz="1.942e-06" iyy="0.009327" iyz="-6.3e-08" izz="0.004921781" />
        </inertial>
    </link>
    
    <joint name="FL_hip_joint" type="revolute">
        <origin rpy="0 0 0" xyz="0.2508 0.065 -0.045" />
        <parent link="trunk" />
        <child link="FL_hip" />
        <axis xyz="1 0 0" />
        <dynamics damping="0.05" friction="0.01" />
        <limit effort="80" lower="-0.87" upper="0.87" velocity="20" />
    </joint>
    <link name="FL_hip">
        <visual>
            <origin rpy="0 0 0" xyz="0 0 0" />
            <geometry>
                <mesh filename="package://w1_description/meshes/LF_hip.STL" scale="1 1 1" />
            </geometry>
        </visual>
        <inertial>
            <origin rpy="0 0 0" xyz="0.057951 0.00922 -1.7e-05" />
            <mass value="1.543" />
            <inertia ixx="0.001250053" ixy="-3.0903e-05" ixz="-4.03e-06" iyy="0.002049507" iyz="5.045e-06" izz="0.001568073" />
        </inertial>
    </link>
    <joint name="FL_thigh_joint" type="revolute">
        <origin rpy="0 0 0" xyz="0.064 0.0363 0" />
        <parent link="FL_hip" />
        <child link="FL_thigh" />
        <axis xyz="0 1 0" />
        <dynamics damping="0.05" friction="0.01" />
        <limit effort="80" lower="-2.27" upper="1.22" velocity="20" />
    </joint>
    <link name="FL_thigh">
        <visual>
            <origin rpy="0 0 0" xyz="0 0 0" />
            <geometry>
                <mesh filename="package://w1_description/meshes/LF_thigh.STL" scale="1 1 1" />
            </geometry>
        </visual>
        <inertial>
            <origin rpy="0 0 0" xyz="-0.061914 0.061328 0.00435" />
            <mass value="2.997" />
            <inertia ixx="0.005164125" ixy="0.00579372" ixz="0.001694032" iyy="0.036812985" iyz="-0.000522747" izz="0.038207062" />
        </inertial>
    </link>
    <joint name="FL_calf_joint" type="revolute">
        <origin rpy="0 0 0" xyz="-0.28 0.09075 0" />
        <parent link="FL_thigh" />
        <child link="FL_calf" />
        <axis xyz="0 1 0" />
        <dynamics damping="0.05" friction="0.01" />
        <limit effort="80" lower="0" upper="2.0943951023932" velocity="20" />
    </joint>
    <link name="FL_calf">
        <visual>
            <origin rpy="0 0 0" xyz="0 0 0" />
            <geometry>
                <mesh filename="package://w1_description/meshes/LF_calf.STL" scale="1 1 1" />
            </geometry>
        </visual>
        <collision>
            <origin rpy="0 0.680678408 0" xyz="0.10876 0 -0.08805" />
            <geometry>
                <box size="0.28 0.023 0.0451" />
            </geometry>
        </collision>
        <inertial>
            <origin rpy="0 0 0" xyz="0.175672 0.004984 -0.145368" />
            <mass value="1.405" />
            <inertia ixx="0.006518228" ixy="-0.000248509" ixz="0.006450451" iyy="0.014553507" iyz="0.000233879" izz="0.008539584" />
        </inertial>
    </link>
    <joint name="FL_foot_joint" type="revolute">
        <origin rpy="0 -0.3 0" xyz="0.21449 0.03459 -0.17998" />
        <parent link="FL_calf" />
        <child link="FL_foot" />
        <axis xyz="0 1 0" />
        <dynamics friction="1.0" />
        <limit effort="40" lower="-999999" upper="999999" velocity="20" />
    </joint>
    <link name="FL_foot">
        <visual>
            <origin rpy="0 0 0" xyz="0 0 0" />
            <geometry>
                <mesh filename="package://w1_description/meshes/LF_wheel.STL" scale="1 1 1" />
            </geometry>
        </visual>
        <collision>
            <origin rpy="1.5707963267948966 0 0" xyz="0 0 0" />
            <geometry>
                <cylinder length="0.017" radius="0.127" />
            </geometry>
        </collision>
        <inertial>
            <origin rpy="0 0 0" xyz="-3.6e-05 0.000971 -3.9e-05" />
            <mass value="0.995" />
            <inertia ixx="0.004921306" ixy="7e-09" ixz="1.942e-06" iyy="0.009327" iyz="6.3e-08" izz="0.004921781" />
        </inertial>
    </link>

    <joint name="RR_hip_joint" type="revolute">
        <origin rpy="0 0 0" xyz="-0.2508 -0.065 -0.045" />
        <parent link="trunk" />
        <child link="RR_hip" />
        <axis xyz="1 0 0" />
        <dynamics damping="0.05" friction="0.01" />
        <limit effort="80" lower="-0.87" upper="0.87" velocity="20" />
    </joint>
    <link name="RR_hip">
        <visual>
            <origin rpy="0 0 0" xyz="0 0 0" />
            <geometry>
                <mesh filename="package://w1_description/meshes/RH_hip.STL" scale="1 1 1" />
            </geometry>
        </visual>
        <inertial>
            <origin rpy="0 0 0" xyz="-0.057951 -0.00922 -1.7e-05" />
            <mass value="1.543" />
            <inertia ixx="0.001250053" ixy="-3.0903e-05" ixz="4.03e-06" iyy="0.002049507" iyz="-5.045e-06" izz="0.001568073" />
        </inertial>
    </link>
    <joint name="RR_thigh_joint" type="revolute">
        <origin rpy="0 0 0" xyz="-0.064 -0.0363 0" />
        <parent link="RR_hip" />
        <child link="RR_thigh" />
        <axis xyz="0 1 0" />
        <dynamics damping="0.05" friction="0.01" />
        <limit effort="80" lower="-2.27" upper="1.22" velocity="20" />
    </joint>
    <link name="RR_thigh">
        <visual>
            <origin rpy="0 0 0" xyz="0 0 0" />
            <geometry>
                <mesh filename="package://w1_description/meshes/RH_thigh.STL" scale="1 1 1" />
            </geometry>
        </visual>
        <inertial>
            <origin rpy="0 0 0" xyz="-0.061914 -0.061328 0.00435" />
            <mass value="2.997" />
            <inertia ixx="0.005164125" ixy="-0.00579372" ixz="0.001694032" iyy="0.036812985" iyz="0.000522747" izz="0.038207062" />
        </inertial>
    </link>
    <joint name="RR_calf_joint" type="revolute">
        <origin rpy="0 0 0" xyz="-0.28 -0.09075 0" />
        <parent link="RR_thigh" />
        <child link="RR_calf" />
        <axis xyz="0 1 0" />
        <dynamics damping="0.05" friction="0.01" />
        <limit effort="80" lower="0" upper="2.0943951023932" velocity="20" />
    </joint>
    <link name="RR_calf">
        <visual>
            <origin rpy="0 0 0" xyz="0 0 0" />
            <geometry>
                <mesh filename="package://w1_description/meshes/RH_calf.STL" scale="1 1 1" />
            </geometry>
        </visual>
        <collision>
            <origin rpy="0 0.680678408 0" xyz="0.10876 0 -0.08805" />
            <geometry>
                <box size="0.28 0.023 0.0451" />
            </geometry>
        </collision>
        <inertial>
            <origin rpy="0 0 0" xyz="0.175672 -0.004984 -0.145368" />
            <mass value="1.405" />
            <inertia ixx="0.006518228" ixy="0.000248509" ixz="0.006450451" iyy="0.014553507" iyz="-0.000233879" izz="0.008539584" />
        </inertial>
    </link>
    <joint name="RR_foot_joint" type="revolute">
        <origin rpy="0 -0.3 0" xyz="0.21449 -0.03459 -0.17998" />
        <parent link="RR_calf" />
        <child link="RR_foot" />
        <axis xyz="0 1 0" />
        <dynamics friction="1.0" />
        <limit effort="40" lower="-999999" upper="999999" velocity="20" />
    </joint>
    <link name="RR_foot">
        <visual>
            <origin rpy="0 0 0" xyz="0 0 0" />
            <geometry>
                <mesh filename="package://w1_description/meshes/RH_wheel.STL" scale="1 1 1" />
            </geometry>
        </visual>
        <collision>
            <origin rpy="1.5707963267948966 0 0" xyz="0 0 0" />
            <geometry>
                <cylinder length="0.017" radius="0.127" />
            </geometry>
        </collision>
        <inertial>
            <origin rpy="0 0 0" xyz="-3.6e-05 -0.000971 -3.9e-05" />
            <mass value="0.995" />
            <inertia ixx="0.004921306" ixy="-7e-09" ixz="1.942e-06" iyy="0.009327" iyz="-6.3e-08" izz="0.004921781" />
        </inertial>
    </link>

    <joint name="RL_hip_joint" type="revolute">
        <origin rpy="0 0 0" xyz="-0.2508 0.065 -0.045" />
        <parent link="trunk" />
        <child link="RL_hip" />
        <axis xyz="1 0 0" />
        <dynamics damping="0.05" friction="0.01" />
        <limit effort="80" lower="-0.87" upper="0.87" velocity="20" />
    </joint>
    <link name="RL_hip">
        <visual>
            <origin rpy="0 0 0" xyz="0 0 0" />
            <geometry>
                <mesh filename="package://w1_description/meshes/LH_hip.STL" scale="1 1 1" />
            </geometry>
        </visual>
        <inertial>
            <origin rpy="0 0 0" xyz="-0.057951 0.00922 -1.7e-05" />
            <mass value="1.543" />
            <inertia ixx="0.001250053" ixy="3.0903e-05" ixz="4.03e-06" iyy="0.002049507" iyz="5.045e-06" izz="0.001568073" />
        </inertial>
    </link>
    <joint name="RL_thigh_joint" type="revolute">
        <origin rpy="0 0 0" xyz="-0.064 0.0363 0" />
        <parent link="RL_hip" />
        <child link="RL_thigh" />
        <axis xyz="0 1 0" />
        <dynamics damping="0.05" friction="0.01" />
        <limit effort="80" lower="-2.27" upper="1.22" velocity="20" />
    </joint>
    <link name="RL_thigh">
        <visual>
            <origin rpy="0 0 0" xyz="0 0 0" />
            <geometry>
                <mesh filename="package://w1_description/meshes/LH_thigh.STL" scale="1 1 1" />
            </geometry>
        </visual>
        <inertial>
            <origin rpy="0 0 0" xyz="-0.061914 0.061328 0.00435" />
            <mass value="2.997" />
            <inertia ixx="0.005164125" ixy="0.00579372" ixz="0.001694032" iyy="0.036812985" iyz="-0.000522747" izz="0.038207062" />
        </inertial>
    </link>
    <joint name="RL_calf_joint" type="revolute">
        <origin rpy="0 0 0" xyz="-0.28 0.09075 0" />
        <parent link="RL_thigh" />
        <child link="RL_calf" />
        <axis xyz="0 1 0" />
        <dynamics damping="0.05" friction="0.01" />
        <limit effort="80" lower="0" upper="2.0943951023932" velocity="20" />
    </joint>
    <link name="RL_calf">
        <visual>
            <origin rpy="0 0 0" xyz="0 0 0" />
            <geometry>
                <mesh filename="package://w1_description/meshes/LH_calf.STL" scale="1 1 1" />
            </geometry>
        </visual>
        <collision>
            <origin rpy="0 0.680678408 0" xyz="0.10876 0 -0.08805" />
            <geometry>
                <box size="0.28 0.023 0.0451" />
            </geometry>
        </collision>
        <inertial>
            <origin rpy="0 0 0" xyz="0.175672 0.004984 -0.145368" />
            <mass value="1.405" />
            <inertia ixx="0.006518228" ixy="-0.000248509" ixz="0.006450451" iyy="0.014553507" iyz="0.000233879" izz="0.008539584" />
        </inertial>
    </link>
    <joint name="RL_foot_joint" type="revolute">
        <origin rpy="0 -0.3 0" xyz="0.21449 0.03459 -0.17998" />
        <parent link="RL_calf" />
        <child link="RL_foot" />
        <axis xyz="0 1 0" />
        <dynamics friction="1.0" />
        <limit effort="40" lower="-999999" upper="999999" velocity="20" />
    </joint>
    <link name="RL_foot">
        <visual>
            <origin rpy="0 0 0" xyz="0 0 0" />
            <geometry>
                <mesh filename="package://w1_description/meshes/LH_wheel.STL" scale="1 1 1" />
            </geometry>
        </visual>
        <collision>
            <origin rpy="1.5707963267948966 0 0" xyz="0 0 0" />
            <geometry>
                <cylinder length="0.017" radius="0.127" />
            </geometry>
        </collision>
        <inertial>
            <origin rpy="0 0 0" xyz="-3.6e-05 0.000971 -3.9e-05" />
            <mass value="0.995" />
            <inertia ixx="0.004921306" ixy="7e-09" ixz="1.942e-06" iyy="0.009327" iyz="6.3e-08" izz="0.004921781" />
        </inertial>
    </link>

</robot>